Workbook

Sheet Model
A1: Expense | B1: Date | C1: Amount | D1: Category | E1: Subcategory
A2: Manjal, Kunkumam, Uppu | B2: 46174 | C2: 20 | D2: {=_xlfn.XLOOKUP(A2, Categories!A:A, Categories!B:B, "Check Category", 0)} -> Check Category | E2: {=_xlfn.XLOOKUP(A2, Categories!A:A, Categories!C:C, "Check subcategory", 0)} -> Check subcategory
D3: {=_xlfn.XLOOKUP(A3, Categories!A:A, Categories!B:B, "Check Category", 0)} -> Check Category | E3: {=_xlfn.XLOOKUP(A3, Categories!A:A, Categories!C:C, "Check subcategory", 0)} -> Check subcategory
D4: {=_xlfn.XLOOKUP(A4, Categories!A:A, Categories!B:B, "Check Category", 0)} -> Check Category | E4: {=_xlfn.XLOOKUP(A4, Categories!A:A, Categories!C:C, "Check subcategory", 0)} -> Check subcategory
D5: {=_xlfn.XLOOKUP(A5, Categories!A:A, Categories!B:B, "Check Category", 0)} -> Check Category | E5: {=_xlfn.XLOOKUP(A5, Categories!A:A, Categories!C:C, "Check subcategory", 0)} -> Check subcategory
D6: {=_xlfn.XLOOKUP(A6, Categories!A:A, Categories!B:B, "Check Category", 0)} -> Check Category | E6: {=_xlfn.XLOOKUP(A6, Categories!A:A, Categories!C:C, "Check subcategory", 0)} -> Check subcategory
D7: {=_xlfn.XLOOKUP(A7, Categories!A:A, Categories!B:B, "Check Category", 0)} -> Check Category | E7: {=_xlfn.XLOOKUP(A7, Categories!A:A, Categories!C:C, "Check subcategory", 0)} -> Check subcategory
D8: {=_xlfn.XLOOKUP(A8, Categories!A:A, Categories!B:B, "Check Category", 0)} -> Check Category | E8: {=_xlfn.XLOOKUP(A8, Categories!A:A, Categories!C:C, "Check subcategory", 0)} -> Check subcategory
D9: {=_xlfn.XLOOKUP(A9, Categories!A:A, Categories!B:B, "Check Category", 0)} -> Check Category | E9: {=_xlfn.XLOOKUP(A9, Categories!A:A, Categories!C:C, "Check subcategory", 0)} -> Check subcategory
D10: {=_xlfn.XLOOKUP(A10, Categories!A:A, Categories!B:B, "Check Category", 0)} -> Check Category | E10: {=_xlfn.XLOOKUP(A10, Categories!A:A, Categories!C:C, "Check subcategory", 0)} -> Check subcategory
D11: {=_xlfn.XLOOKUP(A11, Categories!A:A, Categories!B:B, "Check Category", 0)} -> Check Category | E11: {=_xlfn.XLOOKUP(A11, Categories!A:A, Categories!C:C, "Check subcategory", 0)} -> Check subcategory
D12: {=_xlfn.XLOOKUP(A12, Categories!A:A, Categories!B:B, "Check Category", 0)} -> Check Category | E12: {=_xlfn.XLOOKUP(A12, Categories!A:A, Categories!C:C, "Check subcategory", 0)} -> Check subcategory
D13: {=_xlfn.XLOOKUP(A13, Categories!A:A, Categories!B:B, "Check Category", 0)} -> Check Category | E13: {=_xlfn.XLOOKUP(A13, Categories!A:A, Categories!C:C, "Check subcategory", 0)} -> Check subcategory
D14: {=_xlfn.XLOOKUP(A14, Categories!A:A, Categories!B:B, "Check Category", 0)} -> Check Category | E14: {=_xlfn.XLOOKUP(A14, Categories!A:A, Categories!C:C, "Check subcategory", 0)} -> Check subcategory
... D75: {=_xlfn.XLOOKUP(A75, Categories!A:A, Categories!B:B, "Check Category", 0)} -> Check Category | E75: {=_xlfn.XLOOKUP(A75, Categories!A:A, Categories!C:C, "Check subcategory", 0)} -> Check subcategory

Sheet Categories
A1: Expense | B1: Category | C1: Subcategory
A2: Newspaper | B2: House | C2: Newspaper
A3: Milk | B3: House | C3: Milk
A4: Gas | B4: House | C4: Gas
A5: EB Bill | B5: House | C5: EB
A6: Ration | B6: House | C6: Ration
A7: Water | B7: House | C7: Common
A8: Wifi Recharge | B8: House | C8: Common
A9: Ravi Medicine | B9: Medicine | C9: Ravi
A10: Prabha Medicine | B10: Medicine | C10: Prabha
A11: Karthick Medicine | B11: Medicine | C11: Karthick
A12: Medicine | B12: Medicine | C12: Common
... A40: Ravi Mobile Recharge | B40: Mobile | C40: Ravi

Sheet January
A1: Expense | B1: Date | C1: Amount | D1: Category | E1: Subcategory
A2: Manjal, Kunkumam, Uppu | B2: 46023 | C2: 20
A3: Bus fare | B3: 46023 | C3: 32 | D3: Transport | E3: Bus
A4: Archanai | B4: 46023 | C4: 100 | D4: Temple | E4: Donation
A5: Medicine Prabha | B5: 46023 | C5: 90 | D5: Medicine | E5: Prabha
A6: Vegetable | B6: 46023 | C6: 10 | D6: Grocery | E6: Vegetables
A7: Bus fare | B7: 46025 | C7: 7 | D7: Transport | E7: Bus
A8: Provision | B8: 46025 | C8: 177 | D8: Grocery | E8: Provision
A9: Fruits | B9: 46025 | C9: 10 | D9: Grocery | E9: Fruits
A10: Newspaper | B10: 46025 | C10: 60 | D10: Newspaper
A11: Milk | B11: 46026 | C11: 1755 | D11: Milk
A12: EB Bill | B12: 46027 | C12: 526 | D12: Bills | E12: Electricity
A13: Vegetable | B13: 46143 | C13: 50 | D13: Grocery | E13: Vegetables
A14: Bus fare | B14: 46029 | C14: 11 | D14: Transport | E14: Bus
A15: Auto | B15: 46029 | C15: 50 | D15: Transport | E15: Auto
A16: Provision | B16: 46029 | C16: 147 | D16: Grocery | E16: Provision
A17: Dustbin | B17: 46029 | C17: 350
A18: Diet foods | B18: 46029 | C18: 1660 | D18: Grocery | E18: Provision
A19: Bread | B19: 46029 | C19: 50 | D19: Grocery
A20: Fruits | B20: 46029 | C20: 270
A21: Gas | B21: 46029 | C21: 900 | D21: Bills | E21: Gas
A22: Vegetable | B22: 46029 | C22: 110 | D22: Grocery | E22: Vegetables
A23: Vegetable | B23: 46030 | C23: 100 | D23: Grocery | E23: Vegetables
A24: Flour grinding | B24: 46030 | C24: 95
A25: Vegetable cutter | B25: 46030 | C25: 45
A26: Gas Insurance | B26: 46030 | C26: 235 | D26: Bills | E26: Gas
A27: Provision | B27: 46031 | C27: 485 | D27: Grocery | E27: Provision
A28: Hearing Aid Repair | B28: 46031 | C28: 1560 | D28: Hospital | E28: Doctor
A29: Snacks | B29: 46031 | C29: 150 | D29: Food | E29: Outside
A30: Water pot | B30: 46031 | C30: 250
A31: Pongal pot | B31: 46031 | C31: 250
A32: Pongal Aduppu | B32: 46031 | C32: 250
A33: Courier person | B33: 46031 | C33: 50
A34: Water person expenses | B34: 46031 | C34: 200 | D34: Bills | E34: Water operator
A35: Auto | B35: 46031 | C35: 200 | D35: Transport | E35: Auto
A36: Vegetables | B36: 46032 | C36: 790 | D36: Grocery | E36: Vegetables
A37: Provision | B37: 46032 | C37: 188 | D37: Grocery | E37: Provision
A38: Auto | B38: 46032 | C38: 70 | D38: Transport | E38: Auto
A39: Pongal Gift | B39: 46033 | C39: 3000
A40: Bus fare | B40: 46033 | C40: 22 | D40: Transport | E40: Bus
...

Sheet February
A1: Expense | B1: Date | C1: Amount | D1: Category | E1: Subcategory
A2: Manjal, Kunkumam, Uppu | B2: 46054 | C2: 20
A3: Phone Recharge Ravi | B3: 46054 | C3: 799 | D3: Recharge | E3: Phone
A4: LIC premium | B4: 46024 | C4: 1675 | D4: Insurance | E4: Premium
A5: Vegetables | B5: 46056 | C5: 284 | D5: Grocery | E5: Vegetables
A6: Taxi for booking mandapam | B6: 46056 | C6: 504 | D6: Transport | E6: Taxi
A7: Tea | B7: 46056 | C7: 20 | D7: Food | E7: Outside
A8: Medicine | B8: 46056 | C8: 308 | D8: Medicine | E8: Ravi
A9: Auto | B9: 46056 | C9: 333 | D9: Transport | E9: Auto
A10: Ticket | B10: 46056 | C10: 20
A11: Taxi | B11: 46056 | C11: 291 | D11: Transport | E11: Taxi
A12: Bus | B12: 46057 | C12: 68 | D12: Transport | E12: Bus
A13: Grocery | B13: 46057 | C13: 358 | D13: Grocery | E13: Provision
A14: Toothpaste | B14: 46057 | C14: 330 | D14: House Essentials | E14: Toiletries
A15: Bus | B15: 46059 | C15: 17 | D15: Transport | E15: Bus
A16: Aadhar card | B16: 46059 | C16: 75
A17: Vegetables | B17: 46059 | C17: 60 | D17: Grocery | E17: Vegetables
A18: Bus | B18: 46059 | C18: 7 | D18: Transport | E18: Bus
A19: Elaneer | B19: 46059 | C19: 50
A20: Milk | B20: 46059 | C20: 2106 | D20: Grocery | E20: Milk
A21: Vegetables | B21: 46060 | C21: 865 | D21: Grocery | E21: Vegetables
A22: Chocolate | B22: 46060 | C22: 90
A23: Auto | B23: 46060 | C23: 90
A24: Batter | B24: 46060 | C24: 80
A25: Snacks | B25: 46060 | C25: 80 | D25: Food
A26: Fruits | B26: 46061 | C26: 260 | D26: Grocery | E26: Fruits
A27: Grocery | B27: 46061 | C27: 282 | D27: Grocery | E27: Provision
A28: Newspaper | B28: 46061 | C28: 30
A29: Blood test | B29: 46061 | C29: 20 | E29: Ravi
A30: Elaneer | B30: 46061 | C30: 50 | D30: Food | E30: Outside
A31: Auto | B31: 46063 | C31: 50 | D31: Transport | E31: Auto
A32: Provision | B32: 46063 | C32: 394 | D32: Grocery | E32: Provision
A33: Provision | B33: 46063 | C33: 1877 | D33: Grocery | E33: Provision
A34: Snacks | B34: 46063 | C34: 100 | D34: Food | E34: Outside
A35: Bus | B35: 46064 | C35: 11 | D35: Transport | E35: Bus
A36: Juice | B36: 46064 | C36: 50 | D36: Food | E36: Outside
A37: Fruits | B37: 46064 | C37: 70 | D37: Grocery | E37: Fruits
A38: Auto | B38: 46064 | C38: 100 | D38: Transport | E38: Auto
A39: Ration | B39: 46064 | C39: 150 | D39: Grocery | E39: Ration
A40: Elaneer | B40: 46064 | C40: 50 | D40: Food | E40: Outside
...

Sheet March
A1: Expense | B1: Date | C1: Amount | D1: Category | E1: Subcategory
A2: Manjal, Kunkumam, Uppu | B2: 46082 | C2: 20
A3: Newspaper | B3: 46082 | C3: 40 | D3: House Expenses | E3: Common
A4: Snacks | B4: 46082 | C4: 40 | D4: Food | E4: Outside
A5: Provision | B5: 46084 | C5: 674 | D5: Grocery | E5: Provision
A6: Auto | B6: 46084 | C6: 30 | D6: Transport | E6: Auto
A7: Bus | B7: 46084 | C7: 5 | D7: Transport | E7: Bus
A8: Temple | B8: 46084 | C8: 10
A9: Gas | B9: 46086 | C9: 900
A10: Milk | B10: 46086 | C10: 1863 | D10: Grocery | E10: Milk
A11: Grocery | B11: 46086 | C11: 521 | D11: Grocery
A12: Bus | B12: 46086 | C12: 5 | D12: Transport | E12: Bus
A13: Medicine | B13: 46086 | C13: 25
A14: Knife sharpening | B14: 46086 | C14: 315 | D14: House Expenses | E14: Common
A15: Medicine | B15: 46086 | C15: 110
A16: Dinner | B16: 46086 | C16: 257 | D16: Food | E16: Order
A17: Fruits | B17: 46087 | C17: 150 | D17: Grocery | E17: Fruits
A18: Oil | B18: 46087 | C18: 265 | D18: Grocery | E18: Provision
A19: Vegetables | B19: 46087 | C19: 24 | D19: Grocery | E19: Vegetables
A20: Elaneer | B20: 46087 | C20: 50 | D20: Food | E20: Outside
A21: Bus | B21: 46087 | C21: 5 | D21: Transport | E21: Bus
A22: Food | B22: 46087 | C22: 194 | D22: Food | E22: Outside
A23: Ration | B23: 46088 | C23: 170 | D23: Grocery | E23: Ration
A24: Bus | B24: 46088 | C24: 5 | D24: Transport | E24: Bus
A25: Auto | B25: 46088 | C25: 70 | D25: Transport | E25: Auto
A26: Batter | B26: 46088 | C26: 60 | D26: Grocery
A27: Vegetables | B27: 46088 | C27: 780 | D27: Grocery | E27: Vegetables
A28: Fruits | B28: 46088 | C28: 60 | D28: Grocery | E28: Fruits
A29: Auto | B29: 46088 | C29: 50 | D29: Transport | E29: Auto
A30: Snacks | B30: 46088 | C30: 40 | D30: Food | E30: Outside
A31: Bus | B31: 46088 | C31: 10 | D31: Transport | E31: Bus
A32: Newspaper | B32: 46089 | C32: 20 | D32: House Expenses | E32: Common
A33: Medicine | B33: 46090 | C33: 327 | D33: Medicine | E33: Ravi
A34: Medicine | B34: 46091 | C34: 75 | D34: Medicine | E34: Prabha
A35: Auto | B35: 46091 | C35: 50 | D35: Transport | E35: Auto
A36: Bus | B36: 46091 | C36: 5 | D36: Transport | E36: Bus
A37: B12 Injection | B37: 46091 | C37: 50 | D37: Medicine | E37: Prabha
A38: Provision | B38: 46091 | C38: 362 | D38: Grocery | E38: Provision
... A61: Snacks | B61: 46097 | C61: 110 | D61: Food | E61: Outside
A62: Panjangam | B62: 46097 | C62: 82 | D62: Pooja
...

Sheet April
A1: Expense | B1: Date | C1: Amount | D1: Category | E1: Subcategory
A2: Manjal, Kunkumam, Uppu | B2: 46113 | C2: 20
A3: Milk | B3: 46113 | C3: 105 | D3: Grocery
A4: Fruits | B4: 46113 | C4: 488 | D4: Grocery | E4: Vegetables
A5: Provision | B5: 46116 | C5: 183 | D5: Grocery | E5: Provision
A6: Milk | B6: 46117 | C6: 105 | D6: Grocery
A7: Hardware | B7: 46118 | C7: 245 | D7: House Expenses | E7: Common
A8: Milk | B8: 46118 | C8: 90 | D8: Grocery
A9: Plumber | B9: 46118 | C9: 350 | D9: House Expenses | E9: Maintainence
A10: Auto | B10: 46118 | C10: 200 | D10: Transport | E10: Auto
A11: Tea | B11: 46118 | C11: 105 | D11: Food | E11: Outside
A12: Maavadu | B12: 46118 | C12: 450 | D12: Grocery | E12: Provision
A13: Provision | B13: 46118 | C13: 859 | D13: Grocery | E13: Provision
A14: Chapathi | B14: 46118 | C14: 100 | D14: Grocery
A15: Medicine | B15: 46118 | C15: 76 | D15: Medicine | E15: Ravi
A16: Auto | B16: 46118 | C16: 300 | D16: Transport | E16: Auto
A17: Milk | B17: 46119 | C17: 1998 | D17: Grocery | E17: Milk
A18: Temple | B18: 46119 | C18: 100 | D18: Temple
A19: Auto | B19: 46119 | C19: 290 | D19: Transport | E19: Auto
A20: Fruits | B20: 46119 | C20: 350 | D20: Grocery | E20: Fruits
A21: Vegetables | B21: 46120 | C21: 489 | D21: Grocery | E21: Vegetables
A22: Auto | B22: 46120 | C22: 150 | D22: Transport | E22: Auto
A23: B12 Injection | B23: 46120 | C23: 84 | D23: Transport | E23: Auto
A24: Provision | B24: 46120 | C24: 750 | D24: Grocery | E24: Provision
A25: Auto | B25: 46122 | C25: 200 | D25: Transport | E25: Auto
A26: Post | B26: 46122 | C26: 144 | D26: House Expenses | E26: Common
A27: Provision | B27: 46122 | C27: 293 | D27: Grocery | E27: Provision
A28: Medicine | B28: 46123 | C28: 508 | D28: Medicine | E28: Ayurvedha
A29: Gas | B29: 46123 | C29: 960 | D29: House Expenses | E29: Essentials
A30: Newspaper | B30: 46123 | C30: 60 | D30: House Expenses | E30: Newspaper
A31: Aadhar card | B31: 46123 | C31: 150
A32: Vegetables | B32: 46123 | C32: 823 | D32: Grocery | E32: Provision
A33: Batter | B33: 46123 | C33: 60 | D33: Grocery
A34: Snacks | B34: 46123 | C34: 75 | D34: Food | E34: Outside
A35: Auto | B35: 46123 | C35: 50 | D35: Transport | E35: Auto
A36: Fruits | B36: 46123 | C36: 144 | D36: Grocery | E36: Fruits
A37: Post | B37: 46124 | C37: 200 | D37: House Expenses | E37: Common
A38: Bus | B38: 46125 | C38: 5 | D38: Transport | E38: Bus
A39: Auto | B39: 46125 | C39: 50 | D39: Transport | E39: Auto
A40: Ration | B40: 46125 | C40: 220 | D40: Grocery | E40: Ration
...

Sheet May
A1: Expense | B1: Date | C1: Amount | D1: Category | E1: Subcategory
A2: Manjal, Kunkumam, Uppu | B2: 46143 | C2: 20
A3: Grocery | B3: 46143 | C3: 119 | D3: Grocery | E3: Provision
A4: ORS | B4: 46143 | C4: 90 | D4: Medicine | E4: Ravi
A5: Provision | B5: 46144 | C5: 429 | D5: Grocery | E5: Provision
A6: Newspaper | B6: 46145 | C6: 50 | D6: House | E6: Newspaper
A7: Vegetables | B7: 46145 | C7: 416 | D7: Grocery | E7: Vegetables
A8: Provision | B8: 46147 | C8: 513 | D8: Grocery | E8: Provision
A9: Milk | B9: 46147 | C9: 2079 | D9: House | E9: Milk
A10: Bus | B10: 46148 | C10: 81 | D10: Transport | E10: Bus
A11: Temple | B11: 46148 | C11: 100 | D11: Pooja
A12: Dinner | B12: 46148 | C12: 732 | D12: Food | E12: Order
A13: Provision | B13: 46149 | C13: 733 | D13: Grocery | E13: Provision
A14: Provision | B14: 46150 | C14: 923 | D14: Grocery | E14: Provision
A15: Vegetables | B15: 46151 | C15: 940 | D15: Grocery | E15: Vegetables
A16: Auto | B16: 46151 | C16: 120 | D16: Transport | E16: Auto
A17: Maavu | B17: 46151 | C17: 60 | D17: Grocery | E17: Everyday
A18: Soap | B18: 46152 | C18: 37 | D18: House | E18: Common
A19: Provision | B19: 46152 | C19: 215 | D19: Grocery | E19: Provision
A20: Nellikai | B20: 46152 | C20: 70 | D20: Grocery | E20: Fruits
A21: Fruits | B21: 46152 | C21: 71 | D21: Grocery | E21: Fruits
A22: Medicine | B22: 46152 | C22: 69 | D22: Medicine | E22: Eyedrops
A23: Gas | B23: 46153 | C23: 960 | D23: House | E23: Gas
... A44: Sukku coffee | B44: 46157 | C44: 106 | D44: Grocery | E44: Provision
A45: Pooja items | B45: 46158 | C45: 240 | D45: Pooja
A46: Medicine | B46: 46158 | C46: 25 | D46: Medicine | E46: Common
A47: Pooja items | B47: 46158 | C47: 60 | D47: Pooja
A48: Ration | B48: 46158 | C48: 170 | D48: House | E48: Common
A49: Fruits | B49: 46158 | C49: 150 | D49: Grocery | E49: Fruits
A50: Medicine | B50: 46158 | C50: 1916 | D50: Medicine | E50: Ravi
A51: Newspaper | B51: 46159 | C51: 50 | D51: House | E51: Newspaper
A52: Water | B52: 46160 | C52: 400 | D52: House | E52: Common
A53: Provision | B53: 46164 | C53: 475 | D53: Grocery | E53: Everyday
A54: Newspaper | B54: 46166 | C54: 20 | D54: House | E54: Newspaper
A55: TV recharrge | B55: 46166 | C55: 2120 | D55: House | E55: Common
A56: Parcel | B56: 46167 | C56: 165 | D56: Onetime | E56: Valli
A57: Bus | B57: 46167 | C57: 21 | D57: Transport | E57: Bus
A58: Auto | B58: 46167 | C58: 50 | D58: Transport | E58: Auto
A59: Honey | B59: 46167 | C59: 420 | D59: Grocery | E59: Provision
... A69: Vegetables | B69: 46172 | C69: 50 | D69: Grocery | E69: Vegetables
...

Sheet June
A1: Expense | B1: Date | C1: Amount | D1: Category | E1: Subcategory
A2: Manjal, Kunkumam, Uppu | B2: 46174 | C2: 20 | D2: {=_xlfn.XLOOKUP(A2,Categories!A:A, Categories!B:B, "Check Category", 0)} -> Check Category | E2: {=_xlfn.XLOOKUP(A2, Categories!A:A, Categories!C:C, "Check subcategory", 0)} -> Check subcategory
A3: Courier | B3: 46174 | C3: 512 | D3: {=_xlfn.XLOOKUP(A3,Categories!A:A, Categories!B:B, "Check Category", 0)} -> Onetime | E3: {=_xlfn.XLOOKUP(A3, Categories!A:A, Categories!C:C, "Check subcategory", 0)} -> Courier
A4: Gas | B4: 46174 | C4: 950 | D4: {=_xlfn.XLOOKUP(A4,Categories!A:A, Categories!B:B, "Check Category", 0)} -> House | E4: {=_xlfn.XLOOKUP(A4, Categories!A:A, Categories!C:C, "Check subcategory", 0)} -> Gas
A5: Courier | B5: 46174 | C5: 1500 | D5: {=_xlfn.XLOOKUP(A5,Categories!A:A, Categories!B:B, "Check Category", 0)} -> Onetime | E5: {=_xlfn.XLOOKUP(A5, Categories!A:A, Categories!C:C, "Check subcategory", 0)} -> Courier
A6: Water | B6: 46175 | C6: 400 | D6: {=_xlfn.XLOOKUP(A6,Categories!A:A, Categories!B:B, "Check Category", 0)} -> House | E6: {=_xlfn.XLOOKUP(A6, Categories!A:A, Categories!C:C, "Check subcategory", 0)} -> Common
A7: Courier | B7: 46175 | C7: 330 | D7: {=_xlfn.XLOOKUP(A7,Categories!A:A, Categories!B:B, "Check Category", 0)} -> Onetime | E7: {=_xlfn.XLOOKUP(A7, Categories!A:A, Categories!C:C, "Check subcategory", 0)} -> Courier
A8: Provision | B8: 46176 | C8: 611 | D8: {=_xlfn.XLOOKUP(A8,Categories!A:A, Categories!B:B, "Check Category", 0)} -> Provision | E8: {=_xlfn.XLOOKUP(A8, Categories!A:A, Categories!C:C, "Check subcategory", 0)} -> Provision
A9: Bus | B9: 46176 | C9: 38 | D9: {=_xlfn.XLOOKUP(A9,Categories!A:A, Categories!B:B, "Check Category", 0)} -> Transport | E9: {=_xlfn.XLOOKUP(A9, Categories!A:A, Categories!C:C, "Check subcategory", 0)} -> Bus
A10: Auto | B10: 46176 | C10: 70 | D10: {=_xlfn.XLOOKUP(A10,Categories!A:A, Categories!B:B, "Check Category", 0)} -> Transport | E10: {=_xlfn.XLOOKUP(A10, Categories!A:A, Categories!C:C, "Check subcategory", 0)} -> Auto
A11: Auto | B11: 46176 | C11: 120 | D11: {=_xlfn.XLOOKUP(A11,Categories!A:A, Categories!B:B, "Check Category", 0)} -> Transport | E11: {=_xlfn.XLOOKUP(A11, Categories!A:A, Categories!C:C, "Check subcategory", 0)} -> Auto
A12: Bus | B12: 46176 | C12: 20 | D12: {=_xlfn.XLOOKUP(A12,Categories!A:A, Categories!B:B, "Check Category", 0)} -> Transport | E12: {=_xlfn.XLOOKUP(A12, Categories!A:A, Categories!C:C, "Check subcategory", 0)} -> Bus
A13: Medicine | B13: 46176 | C13: 188 | D13: {=_xlfn.XLOOKUP(A13,Categories!A:A, Categories!B:B, "Check Category", 0)} -> Medicine | E13: {=_xlfn.XLOOKUP(A13, Categories!A:A, Categories!C:C, "Check subcategory", 0)} -> Common
... A30: Readymade food | B30: 46183 | C30: 40 | D30: {=_xlfn.XLOOKUP(A30,Categories!A:A, Categories!B:B, "Check Category", 0)} -> Grocery | E30: {=_xlfn.XLOOKUP(A30, Categories!A:A, Categories!C:C, "Check subcategory", 0)} -> Readymade
A31: Dress | B31: 46185 | C31: 360 | D31: Dress | E31: Ravi
A32: Bus | B32: 46185 | C32: 10 | D32: {=_xlfn.XLOOKUP(A32,Categories!A:A, Categories!B:B, "Check Category", 0)} -> Transport | E32: {=_xlfn.XLOOKUP(A32, Categories!A:A, Categories!C:C, "Check subcategory", 0)} -> Bus
A33: Auto | B33: 46185 | C33: 70 | D33: {=_xlfn.XLOOKUP(A33,Categories!A:A, Categories!B:B, "Check Category", 0)} -> Transport | E33: {=_xlfn.XLOOKUP(A33, Categories!A:A, Categories!C:C, "Check subcategory", 0)} -> Auto
A34: Honey | B34: 46185 | C34: 410 | D34: {=_xlfn.XLOOKUP(A34,Categories!A:A, Categories!B:B, "Check Category", 0)} -> Provision | E34: {=_xlfn.XLOOKUP(A34, Categories!A:A, Categories!C:C, "Check subcategory", 0)} -> Honey
A35: Readymade food | B35: 46185 | C35: 42 | D35: {=_xlfn.XLOOKUP(A35,Categories!A:A, Categories!B:B, "Check Category", 0)} -> Grocery | E35: {=_xlfn.XLOOKUP(A35, Categories!A:A, Categories!C:C, "Check subcategory", 0)} -> Readymade
A36: Dry fruits | B36: 46185 | C36: 980 | D36: {=_xlfn.XLOOKUP(A36,Categories!A:A, Categories!B:B, "Check Category", 0)} -> Provision | E36: {=_xlfn.XLOOKUP(A36, Categories!A:A, Categories!C:C, "Check subcategory", 0)} -> Dry fruits
A37: Bus | B37: 46185 | C37: 22 | D37: {=_xlfn.XLOOKUP(A37,Categories!A:A, Categories!B:B, "Check Category", 0)} -> Transport | E37: {=_xlfn.XLOOKUP(A37, Categories!A:A, Categories!C:C, "Check subcategory", 0)} -> Bus
A38: Vegetables | B38: 46185 | C38: 25 | D38: {=_xlfn.XLOOKUP(A38,Categories!A:A, Categories!B:B, "Check Category", 0)} -> Grocery | E38: {=_xlfn.XLOOKUP(A38, Categories!A:A, Categories!C:C, "Check subcategory", 0)} -> Vegetables
A39: Snacks | B39: 46185 | C39: 539 | D39: {=_xlfn.XLOOKUP(A39,Categories!A:A, Categories!B:B, "Check Category", 0)} -> Provision | E39: {=_xlfn.XLOOKUP(A39, Categories!A:A, Categories!C:C, "Check subcategory", 0)} -> Snacks
A40: Auto | B40: 46185 | C40: 234 | D40: {=_xlfn.XLOOKUP(A40,Categories!A:A, Categories!B:B, "Check Category", 0)} -> Transport | E40: {=_xlfn.XLOOKUP(A40, Categories!A:A, Categories!C:C, "Check subcategory", 0)} -> Auto
A41: Valli Medicine | B41: 46185 | C41: 1234 | D41: Medicine | E41: Valli
A42: Doctor fees | B42: 46185 | C42: 300 | D42: Hospital | E42: Valli
A43: Auto | B43: 46186 | C43: 180 | D43: {=_xlfn.XLOOKUP(A43,Categories!A:A, Categories!B:B, "Check Category", 0)} -> Transport | E43: {=_xlfn.XLOOKUP(A43, Categories!A:A, Categories!C:C, "Check subcategory", 0)} -> Auto
A44: Auto | B44: 46186 | C44: 120 | D44: {=_xlfn.XLOOKUP(A44,Categories!A:A, Categories!B:B, "Check Category", 0)} -> Transport | E44: {=_xlfn.XLOOKUP(A44, Categories!A:A, Categories!C:C, "Check subcategory", 0)} -> Auto
A45: Auto | B45: 46187 | C45: 200 | D45: {=_xlfn.XLOOKUP(A45,Categories!A:A, Categories!B:B, "Check Category", 0)} -> Transport | E45: {=_xlfn.XLOOKUP(A45, Categories!A:A, Categories!C:C, "Check subcategory", 0)} -> Auto
A46: Gift | B46: 46187 | C46: 100 | D46: Onetime | E46: Gift
A47: Gift | B47: 46187 | C47: 430 | D47: Onetime | E47: Gift
A48: Pooja Items | B48: 46187 | C48: 160 | D48: {=_xlfn.XLOOKUP(A48,Categories!A:A, Categories!B:B, "Check Category", 0)} -> Temple | E48: {=_xlfn.XLOOKUP(A48, Categories!A:A, Categories!C:C, "Check subcategory", 0)} -> Pooja
A49: Ravi Medicine | B49: 46187 | C49: 985 | D49: {=_xlfn.XLOOKUP(A49,Categories!A:A, Categories!B:B, "Check Category", 0)} -> Medicine | E49: {=_xlfn.XLOOKUP(A49, Categories!A:A, Categories!C:C, "Check subcategory", 0)} -> Ravi
A50: Auto | B50: 46188 | C50: 900 | D50: {=_xlfn.XLOOKUP(A50,Categories!A:A, Categories!B:B, "Check Category", 0)} -> Transport | E50: {=_xlfn.XLOOKUP(A50, Categories!A:A, Categories!C:C, "Check subcategory", 0)} -> Auto
A51: Gift | B51: 46188 | C51: 410 | D51: {=_xlfn.XLOOKUP(A51,Categories!A:A, Categories!B:B, "Check Category", 0)} -> Onetime | E51: {=_xlfn.XLOOKUP(A51, Categories!A:A, Categories!C:C, "Check subcategory", 0)} -> Gift
A52: Medicine | B52: 46188 | C52: 80 | D52: {=_xlfn.XLOOKUP(A52,Categories!A:A, Categories!B:B, "Check Category", 0)} -> Medicine | E52: {=_xlfn.XLOOKUP(A52, Categories!A:A, Categories!C:C, "Check subcategory", 0)} -> Common
A53: Medicine | B53: 46188 | C53: 224 | D53: {=_xlfn.XLOOKUP(A53,Categories!A:A, Categories!B:B, "Check Category", 0)} -> Medicine | E53: {=_xlfn.XLOOKUP(A53, Categories!A:A, Categories!C:C, "Check subcategory", 0)} -> Common
A54: Temple | B54: 46189 | C54: 65 | D54: {=_xlfn.XLOOKUP(A54,Categories!A:A, Categories!B:B, "Check Category", 0)} -> Temple | E54: {=_xlfn.XLOOKUP(A54, Categories!A:A, Categories!C:C, "Check subcategory", 0)} -> Donation
A55: Fruits | B55: 46189 | C55: 85 | D55: {=_xlfn.XLOOKUP(A55,Categories!A:A, Categories!B:B, "Check Category", 0)} -> Grocery | E55: {=_xlfn.XLOOKUP(A55, Categories!A:A, Categories!C:C, "Check subcategory", 0)} -> Fruits
A56: Fruits | B56: 46190 | C56: 220 | D56: {=_xlfn.XLOOKUP(A56,Categories!A:A, Categories!B:B, "Check Category", 0)} -> Grocery | E56: {=_xlfn.XLOOKUP(A56, Categories!A:A, Categories!C:C, "Check subcategory", 0)} -> Fruits
...

Sheet July
A1: Expense | B1: Date | C1: Amount | D1: Category | E1: Subcategory
A2: Manjal, Kunkumam, Uppu | B2: 46204 | C2: 20 | D2: {=_xlfn.XLOOKUP(A2, Categories!A:A, Categories!B:B, "Check Category", 0)} -> Check Category | E2: {=_xlfn.XLOOKUP(A2, Categories!A:A, Categories!C:C, "Check subcategory", 0)} -> Check subcategory
A3: Fruits | B3: 46204 | C3: 130 | D3: {=_xlfn.XLOOKUP(A3, Categories!A:A, Categories!B:B, "Check Category", 0)} -> Grocery | E3: {=_xlfn.XLOOKUP(A3, Categories!A:A, Categories!C:C, "Check subcategory", 0)} -> Fruits
A4: Snacks | B4: 46204 | C4: 100 | D4: {=_xlfn.XLOOKUP(A4, Categories!A:A, Categories!B:B, "Check Category", 0)} -> Provision | E4: {=_xlfn.XLOOKUP(A4, Categories!A:A, Categories!C:C, "Check subcategory", 0)} -> Snacks
A5: Vegetables | B5: 46206 | C5: 314 | D5: {=_xlfn.XLOOKUP(A5, Categories!A:A, Categories!B:B, "Check Category", 0)} -> Grocery | E5: {=_xlfn.XLOOKUP(A5, Categories!A:A, Categories!C:C, "Check subcategory", 0)} -> Vegetables
A6: Gas | B6: 46207 | C6: 990 | D6: {=_xlfn.XLOOKUP(A6, Categories!A:A, Categories!B:B, "Check Category", 0)} -> House | E6: {=_xlfn.XLOOKUP(A6, Categories!A:A, Categories!C:C, "Check subcategory", 0)} -> Gas
A7: Provision | B7: 46207 | C7: 3267 | D7: {=_xlfn.XLOOKUP(A7, Categories!A:A, Categories!B:B, "Check Category", 0)} -> Provision | E7: {=_xlfn.XLOOKUP(A7, Categories!A:A, Categories!C:C, "Check subcategory", 0)} -> Provision
A8: Ravi Medicine | B8: 46207 | C8: 341 | D8: {=_xlfn.XLOOKUP(A8, Categories!A:A, Categories!B:B, "Check Category", 0)} -> Medicine | E8: {=_xlfn.XLOOKUP(A8, Categories!A:A, Categories!C:C, "Check subcategory", 0)} -> Ravi
A9: Vegetables | B9: 46210 | C9: 444 | D9: {=_xlfn.XLOOKUP(A9, Categories!A:A, Categories!B:B, "Check Category", 0)} -> Grocery | E9: {=_xlfn.XLOOKUP(A9, Categories!A:A, Categories!C:C, "Check subcategory", 0)} -> Vegetables
A10: Milk | B10: 46210 | C10: 850 | D10: {=_xlfn.XLOOKUP(A10, Categories!A:A, Categories!B:B, "Check Category", 0)} -> House | E10: {=_xlfn.XLOOKUP(A10, Categories!A:A, Categories!C:C, "Check subcategory", 0)} -> Milk
A11: Bus | B11: 46212 | C11: 21 | D11: {=_xlfn.XLOOKUP(A11, Categories!A:A, Categories!B:B, "Check Category", 0)} -> Transport | E11: {=_xlfn.XLOOKUP(A11, Categories!A:A, Categories!C:C, "Check subcategory", 0)} -> Bus
A12: Provision | B12: 46212 | C12: 180 | D12: {=_xlfn.XLOOKUP(A12, Categories!A:A, Categories!B:B, "Check Category", 0)} -> Provision | E12: {=_xlfn.XLOOKUP(A12, Categories!A:A, Categories!C:C, "Check subcategory", 0)} -> Provision
A13: Honey | B13: 46212 | C13: 288 | D13: {=_xlfn.XLOOKUP(A13, Categories!A:A, Categories!B:B, "Check Category", 0)} -> Provision | E13: {=_xlfn.XLOOKUP(A13, Categories!A:A, Categories!C:C, "Check subcategory", 0)} -> Honey
... A22: Bus | B22: 46214 | C22: 21 | D22: {=_xlfn.XLOOKUP(A22, Categories!A:A, Categories!B:B, "Check Category", 0)} -> Transport | E22: {=_xlfn.XLOOKUP(A22, Categories!A:A, Categories!C:C, "Check subcategory", 0)} -> Bus
A23: House | B23: 46214 | C23: 110 | D23: House | E23: Common
A24: Prabha Medicine | B24: 46214 | C24: 615 | D24: {=_xlfn.XLOOKUP(A24, Categories!A:A, Categories!B:B, "Check Category", 0)} -> Medicine | E24: {=_xlfn.XLOOKUP(A24, Categories!A:A, Categories!C:C, "Check subcategory", 0)} -> Prabha
A25: Silver Tumbler polish | B25: 46214 | C25: 200 | D25: {=_xlfn.XLOOKUP(A25, Categories!A:A, Categories!B:B, "Check Category", 0)} -> Check Category | E25: {=_xlfn.XLOOKUP(A25, Categories!A:A, Categories!C:C, "Check subcategory", 0)} -> Check subcategory
A26: Juice | B26: 46214 | C26: 20 | D26: {=_xlfn.XLOOKUP(A26, Categories!A:A, Categories!B:B, "Check Category", 0)} -> Food | E26: {=_xlfn.XLOOKUP(A26, Categories!A:A, Categories!C:C, "Check subcategory", 0)} -> Outside
A27: Provision | B27: 46214 | C27: 235 | D27: {=_xlfn.XLOOKUP(A27, Categories!A:A, Categories!B:B, "Check Category", 0)} -> Provision | E27: {=_xlfn.XLOOKUP(A27, Categories!A:A, Categories!C:C, "Check subcategory", 0)} -> Provision
A28: Provision | B28: 46214 | C28: 170 | D28: {=_xlfn.XLOOKUP(A28, Categories!A:A, Categories!B:B, "Check Category", 0)} -> Provision | E28: {=_xlfn.XLOOKUP(A28, Categories!A:A, Categories!C:C, "Check subcategory", 0)} -> Provision
A29: Readymade Food | B29: 46215 | C29: 45 | D29: {=_xlfn.XLOOKUP(A29, Categories!A:A, Categories!B:B, "Check Category", 0)} -> Grocery | E29: {=_xlfn.XLOOKUP(A29, Categories!A:A, Categories!C:C, "Check subcategory", 0)} -> Readymade
A30: Vegetables | B30: 46215 | C30: 50 | D30: {=_xlfn.XLOOKUP(A30, Categories!A:A, Categories!B:B, "Check Category", 0)} -> Grocery | E30: {=_xlfn.XLOOKUP(A30, Categories!A:A, Categories!C:C, "Check subcategory", 0)} -> Vegetables
A31: Newspaper | B31: 46215 | C31: 40 | D31: {=_xlfn.XLOOKUP(A31, Categories!A:A, Categories!B:B, "Check Category", 0)} -> House | E31: {=_xlfn.XLOOKUP(A31, Categories!A:A, Categories!C:C, "Check subcategory", 0)} -> Newspaper
A32: House | B32: 46215 | C32: 80 | D32: House | E32: Common
A33: EB Bill | B33: 46216 | C33: 675 | D33: {=_xlfn.XLOOKUP(A33, Categories!A:A, Categories!B:B, "Check Category", 0)} -> House | E33: {=_xlfn.XLOOKUP(A33, Categories!A:A, Categories!C:C, "Check subcategory", 0)} -> EB
A34: Water | B34: 46216 | C34: 500 | D34: {=_xlfn.XLOOKUP(A34, Categories!A:A, Categories!B:B, "Check Category", 0)} -> House | E34: {=_xlfn.XLOOKUP(A34, Categories!A:A, Categories!C:C, "Check subcategory", 0)} -> Common
A35: Snacks | B35: 46216 | C35: 100 | D35: {=_xlfn.XLOOKUP(A35, Categories!A:A, Categories!B:B, "Check Category", 0)} -> Provision | E35: {=_xlfn.XLOOKUP(A35, Categories!A:A, Categories!C:C, "Check subcategory", 0)} -> Snacks
A36: Ravi Medicine | B36: 46216 | C36: 167 | D36: {=_xlfn.XLOOKUP(A36, Categories!A:A, Categories!B:B, "Check Category", 0)} -> Medicine | E36: {=_xlfn.XLOOKUP(A36, Categories!A:A, Categories!C:C, "Check subcategory", 0)} -> Ravi
A37: Fruits | B37: 46217 | C37: 30 | D37: {=_xlfn.XLOOKUP(A37, Categories!A:A, Categories!B:B, "Check Category", 0)} -> Grocery | E37: {=_xlfn.XLOOKUP(A37, Categories!A:A, Categories!C:C, "Check subcategory", 0)} -> Fruits
A38: Snacks | B38: 46217 | C38: 110 | D38: {=_xlfn.XLOOKUP(A38, Categories!A:A, Categories!B:B, "Check Category", 0)} -> Provision | E38: {=_xlfn.XLOOKUP(A38, Categories!A:A, Categories!C:C, "Check subcategory", 0)} -> Snacks
A39: Pooja Items | B39: 46217 | C39: 180 | D39: {=_xlfn.XLOOKUP(A39, Categories!A:A, Categories!B:B, "Check Category", 0)} -> Temple | E39: {=_xlfn.XLOOKUP(A39, Categories!A:A, Categories!C:C, "Check subcategory", 0)} -> Pooja
A40: Pooja Items | B40: 46217 | C40: 80 | D40: {=_xlfn.XLOOKUP(A40, Categories!A:A, Categories!B:B, "Check Category", 0)} -> Temple | E40: {=_xlfn.XLOOKUP(A40, Categories!A:A, Categories!C:C, "Check subcategory", 0)} -> Pooja
A41: Temple | B41: 46217 | C41: 30 | D41: {=_xlfn.XLOOKUP(A41, Categories!A:A, Categories!B:B, "Check Category", 0)} -> Temple | E41: {=_xlfn.XLOOKUP(A41, Categories!A:A, Categories!C:C, "Check subcategory", 0)} -> Donation
A42: Readymade Food | B42: 46217 | C42: 27 | D42: {=_xlfn.XLOOKUP(A42, Categories!A:A, Categories!B:B, "Check Category", 0)} -> Grocery | E42: {=_xlfn.XLOOKUP(A42, Categories!A:A, Categories!C:C, "Check subcategory", 0)} -> Readymade
A43: Pooja Items | B43: 46217 | C43: 80 | D43: {=_xlfn.XLOOKUP(A43, Categories!A:A, Categories!B:B, "Check Category", 0)} -> Temple | E43: {=_xlfn.XLOOKUP(A43, Categories!A:A, Categories!C:C, "Check subcategory", 0)} -> Pooja
A44: Temple | B44: 46217 | C44: 45 | D44: {=_xlfn.XLOOKUP(A44, Categories!A:A, Categories!B:B, "Check Category", 0)} -> Temple | E44: {=_xlfn.XLOOKUP(A44, Categories!A:A, Categories!C:C, "Check subcategory", 0)} -> Donation
... A50: Temple | B50: 46218 | C50: 30 | D50: {=_xlfn.XLOOKUP(A50, Categories!A:A, Categories!B:B, "Check Category", 0)} -> Temple | E50: {=_xlfn.XLOOKUP(A50, Categories!A:A, Categories!C:C, "Check subcategory", 0)} -> Donation
A51: Silver Plate | B51: 46218 | C51: 31500 | D51: Onetime | E51: Gift
A52: Provision | B52: 46218 | C52: 137 | D52: {=_xlfn.XLOOKUP(A52, Categories!A:A, Categories!B:B, "Check Category", 0)} -> Provision | E52: {=_xlfn.XLOOKUP(A52, Categories!A:A, Categories!C:C, "Check subcategory", 0)} -> Provision
A53: Provision | B53: 46218 | C53: 286 | D53: {=_xlfn.XLOOKUP(A53, Categories!A:A, Categories!B:B, "Check Category", 0)} -> Provision | E53: {=_xlfn.XLOOKUP(A53, Categories!A:A, Categories!C:C, "Check subcategory", 0)} -> Provision
...

Sheet August
A1: Expense | B1: Date | C1: Amount | D1: Category | E1: Subcategory
A2: Manjal, Kunkumam, Uppu | B2: 46235 | C2: 20 | D2: {=_xlfn.XLOOKUP(A2, Categories!A:A, Categories!B:B, "Check Category", 0)} -> Check Category | E2: {=_xlfn.XLOOKUP(A2, Categories!A:A, Categories!C:C, "Check subcategory", 0)} -> Check subcategory
A3: Readymade food | B3: 46237 | C3: 100 | D3: {=_xlfn.XLOOKUP(A3, Categories!A:A, Categories!B:B, "Check Category", 0)} -> Grocery | E3: {=_xlfn.XLOOKUP(A3, Categories!A:A, Categories!C:C, "Check subcategory", 0)} -> Readymade
A4: Provision | B4: 46238 | C4: 816 | D4: {=_xlfn.XLOOKUP(A4, Categories!A:A, Categories!B:B, "Check Category", 0)} -> Provision | E4: {=_xlfn.XLOOKUP(A4, Categories!A:A, Categories!C:C, "Check subcategory", 0)} -> Provision
A5: Readymade food | B5: 46239 | C5: 85 | D5: {=_xlfn.XLOOKUP(A5, Categories!A:A, Categories!B:B, "Check Category", 0)} -> Grocery | E5: {=_xlfn.XLOOKUP(A5, Categories!A:A, Categories!C:C, "Check subcategory", 0)} -> Readymade
A6: Bus | B6: 46240 | C6: 38 | D6: {=_xlfn.XLOOKUP(A6, Categories!A:A, Categories!B:B, "Check Category", 0)} -> Transport | E6: {=_xlfn.XLOOKUP(A6, Categories!A:A, Categories!C:C, "Check subcategory", 0)} -> Bus
A7: Auto | B7: 46240 | C7: 80 | D7: {=_xlfn.XLOOKUP(A7, Categories!A:A, Categories!B:B, "Check Category", 0)} -> Transport | E7: {=_xlfn.XLOOKUP(A7, Categories!A:A, Categories!C:C, "Check subcategory", 0)} -> Auto
A8: Readymade food | B8: 46240 | C8: 255 | D8: {=_xlfn.XLOOKUP(A8, Categories!A:A, Categories!B:B, "Check Category", 0)} -> Grocery | E8: {=_xlfn.XLOOKUP(A8, Categories!A:A, Categories!C:C, "Check subcategory", 0)} -> Readymade
A9: Milk | B9: 46240 | C9: 1647 | D9: {=_xlfn.XLOOKUP(A9, Categories!A:A, Categories!B:B, "Check Category", 0)} -> House | E9: {=_xlfn.XLOOKUP(A9, Categories!A:A, Categories!C:C, "Check subcategory", 0)} -> Milk
A10: Juice | B10: 46240 | C10: 50 | D10: {=_xlfn.XLOOKUP(A10, Categories!A:A, Categories!B:B, "Check Category", 0)} -> Food | E10: {=_xlfn.XLOOKUP(A10, Categories!A:A, Categories!C:C, "Check subcategory", 0)} -> Outside
A11: Provision | B11: 46240 | C11: 75 | D11: {=_xlfn.XLOOKUP(A11, Categories!A:A, Categories!B:B, "Check Category", 0)} -> Provision | E11: {=_xlfn.XLOOKUP(A11, Categories!A:A, Categories!C:C, "Check subcategory", 0)} -> Provision
A12: Dress | B12: 46240 | C12: 50 | D12: Onetime | E12: Dress
A13: Dress | B13: 46240 | C13: 1499 | D13: Onetime | E13: Dress
A14: Silver | B14: 46240 | C14: 213 | D14: Onetime | E14: Silver
A15: Dress | B15: 46240 | C15: 2300 | D15: Onetime | E15: Dress
A16: Bus | B16: 46240 | C16: 6 | D16: {=_xlfn.XLOOKUP(A16, Categories!A:A, Categories!B:B, "Check Category", 0)} -> Transport | E16: {=_xlfn.XLOOKUP(A16, Categories!A:A, Categories!C:C, "Check subcategory", 0)} -> Bus
A17: Auto | B17: 46240 | C17: 130 | D17: {=_xlfn.XLOOKUP(A17, Categories!A:A, Categories!B:B, "Check Category", 0)} -> Transport | E17: {=_xlfn.XLOOKUP(A17, Categories!A:A, Categories!C:C, "Check subcategory", 0)} -> Auto
A18: Bus | B18: 46241 | C18: 14 | D18: {=_xlfn.XLOOKUP(A18, Categories!A:A, Categories!B:B, "Check Category", 0)} -> Transport | E18: {=_xlfn.XLOOKUP(A18, Categories!A:A, Categories!C:C, "Check subcategory", 0)} -> Bus
A19: Auto | B19: 46241 | C19: 70 | D19: {=_xlfn.XLOOKUP(A19, Categories!A:A, Categories!B:B, "Check Category", 0)} -> Transport | E19: {=_xlfn.XLOOKUP(A19, Categories!A:A, Categories!C:C, "Check subcategory", 0)} -> Auto
A20: Dress | B20: 46241 | C20: 500 | D20: Onetime | E20: Dress
A21: Readymade food | B21: 46241 | C21: 39 | D21: {=_xlfn.XLOOKUP(A21, Categories!A:A, Categories!B:B, "Check Category", 0)} -> Grocery | E21: {=_xlfn.XLOOKUP(A21, Categories!A:A, Categories!C:C, "Check subcategory", 0)} -> Readymade
A22: Auto | B22: 46242 | C22: 120 | D22: {=_xlfn.XLOOKUP(A22, Categories!A:A, Categories!B:B, "Check Category", 0)} -> Transport | E22: {=_xlfn.XLOOKUP(A22, Categories!A:A, Categories!C:C, "Check subcategory", 0)} -> Auto
A23: Vegetables | B23: 46242 | C23: 890 | D23: {=_xlfn.XLOOKUP(A23, Categories!A:A, Categories!B:B, "Check Category", 0)} -> Grocery | E23: {=_xlfn.XLOOKUP(A23, Categories!A:A, Categories!C:C, "Check subcategory", 0)} -> Vegetables
A24: Provision | B24: 46242 | C24: 344 | D24: {=_xlfn.XLOOKUP(A24, Categories!A:A, Categories!B:B, "Check Category", 0)} -> Provision | E24: {=_xlfn.XLOOKUP(A24, Categories!A:A, Categories!C:C, "Check subcategory", 0)} -> Provision
A25: Snacks | B25: 46242 | C25: 200 | D25: {=_xlfn.XLOOKUP(A25, Categories!A:A, Categories!B:B, "Check Category", 0)} -> Provision | E25: {=_xlfn.XLOOKUP(A25, Categories!A:A, Categories!C:C, "Check subcategory", 0)} -> Snacks
A26: Provision | B26: 46243 | C26: 607 | D26: {=_xlfn.XLOOKUP(A26, Categories!A:A, Categories!B:B, "Check Category", 0)} -> Provision | E26: {=_xlfn.XLOOKUP(A26, Categories!A:A, Categories!C:C, "Check subcategory", 0)} -> Provision
A27: Provision | B27: 46243 | C27: 104 | D27: Provision | E27: Provision
A28: Provision | B28: 46244 | C28: 176 | D28: {=_xlfn.XLOOKUP(A28, Categories!A:A, Categories!B:B, "Check Category", 0)} -> Provision | E28: {=_xlfn.XLOOKUP(A28, Categories!A:A, Categories!C:C, "Check subcategory", 0)} -> Provision
A29: Provision | B29: 46246 | C29: 706 | D29: {=_xlfn.XLOOKUP(A29, Categories!A:A, Categories!B:B, "Check Category", 0)} -> Provision | E29: {=_xlfn.XLOOKUP(A29, Categories!A:A, Categories!C:C, "Check subcategory", 0)} -> Provision
A30: Bus | B30: 46246 | C30: 10 | D30: {=_xlfn.XLOOKUP(A30, Categories!A:A, Categories!B:B, "Check Category", 0)} -> Transport | E30: {=_xlfn.XLOOKUP(A30, Categories!A:A, Categories!C:C, "Check subcategory", 0)} -> Bus
A31: Pooja items | B31: 46246 | C31: 281 | D31: {=_xlfn.XLOOKUP(A31, Categories!A:A, Categories!B:B, "Check Category", 0)} -> Temple | E31: {=_xlfn.XLOOKUP(A31, Categories!A:A, Categories!C:C, "Check subcategory", 0)} -> Pooja
A32: Temple | B32: 46246 | C32: 60 | D32: {=_xlfn.XLOOKUP(A32, Categories!A:A, Categories!B:B, "Check Category", 0)} -> Temple | E32: {=_xlfn.XLOOKUP(A32, Categories!A:A, Categories!C:C, "Check subcategory", 0)} -> Donation
A33: Pooja items | B33: 46246 | C33: 86 | D33: {=_xlfn.XLOOKUP(A33, Categories!A:A, Categories!B:B, "Check Category", 0)} -> Temple | E33: {=_xlfn.XLOOKUP(A33, Categories!A:A, Categories!C:C, "Check subcategory", 0)} -> Pooja
A34: Juice | B34: 46246 | C34: 12 | D34: {=_xlfn.XLOOKUP(A34, Categories!A:A, Categories!B:B, "Check Category", 0)} -> Food | E34: {=_xlfn.XLOOKUP(A34, Categories!A:A, Categories!C:C, "Check subcategory", 0)} -> Outside
A35: Water | B35: 46246 | C35: 200 | D35: {=_xlfn.XLOOKUP(A35, Categories!A:A, Categories!B:B, "Check Category", 0)} -> House | E35: {=_xlfn.XLOOKUP(A35, Categories!A:A, Categories!C:C, "Check subcategory", 0)} -> Common
A36: Newspaper | B36: 46246 | C36: 40 | D36: {=_xlfn.XLOOKUP(A36, Categories!A:A, Categories!B:B, "Check Category", 0)} -> House | E36: {=_xlfn.XLOOKUP(A36, Categories!A:A, Categories!C:C, "Check subcategory", 0)} -> Newspaper
A37: Pooja items | B37: 46246 | C37: 120 | D37: {=_xlfn.XLOOKUP(A37, Categories!A:A, Categories!B:B, "Check Category", 0)} -> Temple | E37: {=_xlfn.XLOOKUP(A37, Categories!A:A, Categories!C:C, "Check subcategory", 0)} -> Pooja
A38: Temple | B38: 46246 | C38: 30 | D38: {=_xlfn.XLOOKUP(A38, Categories!A:A, Categories!B:B, "Check Category", 0)} -> Temple | E38: {=_xlfn.XLOOKUP(A38, Categories!A:A, Categories!C:C, "Check subcategory", 0)} -> Donation
A39: Readymade food | B39: 46247 | C39: 45 | D39: {=_xlfn.XLOOKUP(A39, Categories!A:A, Categories!B:B, "Check Category", 0)} -> Grocery | E39: {=_xlfn.XLOOKUP(A39, Categories!A:A, Categories!C:C, "Check subcategory", 0)} -> Readymade
... A99: Readymade food | B99: 46255 | C99: 199 | D99: {=_xlfn.XLOOKUP(A99, Categories!A:A, Categories!B:B, "Check Category", 0)} -> Grocery | E99: {=_xlfn.XLOOKUP(A99, Categories!A:A, Categories!C:C, "Check subcategory", 0)} -> Readymade
...

Sheet Pivot Table 1
